Workbook
Name AsOfDate: Settings!$B$5
Name CostIndexAlert: Settings!$B$10
Name PalletsPerTrailer: Settings!$B$7
Name PlanWeek: Settings!$B$6
Name TargetFill: Settings!$B$9
Name TargetOnTime: Settings!$B$8

Sheet About
A1: Pool Point Network Planner
A2: Outbound transportation planning workbook. Built by Nana Afari.
A4: What this is | B4: A weekly planning pack for an outbound network of one DC, 8 pool points, 4 linehaul carriers, and 136 stores.
A5: Demand | B5: Seasonality and trend come from real U.S. Census clothing store sales (FRED series MRTSSM448USN).
A6: Simulated | B6: Stores, carriers, rates, and operations are simulated. Pool point cities and road miles are approximate.
A7: As-of date | B7: History runs through the week ending Jul 25, 2026. Forecast covers the next 26 weeks.
A8: Forecast | B8: Holt-Winters won a two-window backtest with 3.5% WAPE at the pool point level.
A10: Sheet | B10: Use it to
A11: Dashboard | B11: Pick a pool point to see its KPIs, 26-week forecast, and trailer needs vs. contract.
A12: KPI Scorecard | B12: Benchmark pool points and carriers against the targets on the Settings sheet.
A13: Volume Forecast | B13: Weekly forecast by lane. Trailers and capacity status are formulas.
A14: Forecast Matrix | B14: Pool point by week heatmap of forecast pallets.
A15: Carrier Outlook | B15: Surge trailers to request from each carrier, plus the outlook notes to send them.
A16: Peak Week Schedule | B16: Store delivery plan for the peak week after change requests and mitigation.
... A21: Settings | B21: Targets and constants used by every formula. Yellow cells are inputs.

Sheet Dashboard
A1: Pool Point Dashboard
A2: Pick a pool point in the yellow cell. Every number and chart below updates.
A4: Pool point | B4: PP03
A5: City | B5: =INDEX('Pool Points'!$B:$B,MATCH($B$4,'Pool Points'!$A:$A,0))&", "&INDEX('Pool Points'!$C:$C,MATCH($B$4,'Pool Points'!$A:$A,0)) -> Worcester, MA
A6: Carrier | B6: =INDEX('Pool Points'!$E:$E,MATCH($B$4,'Pool Points'!$A:$A,0)) -> CARR-B
A8: Avg weekly pallets | B8: YoY volume growth | C8: On-time delivery | D8: Trailer fill | E8: Cost per pallet | F8: Forecast WAPE | G8: Peak forecast week | H8: Weeks over capacity
A9: =INDEX('KPI Scorecard'!$D:$D,MATCH($B$4,'KPI Scorecard'!$A:$A,0)) -> 323.90385 | B9: =INDEX('KPI Scorecard'!$E:$E,MATCH($B$4,'KPI Scorecard'!$A:$A,0)) -> 0.06224773 | C9: =INDEX('KPI Scorecard'!$F:$F,MATCH($B$4,'KPI Scorecard'!$A:$A,0)) -> 0.92548077 | D9: =INDEX('KPI Scorecard'!$H:$H,MATCH($B$4,'KPI Scorecard'!$A:$A,0)) -> 0.80473005 | E9: =INDEX('KPI Scorecard'!$J:$J,MATCH($B$4,'KPI Scorecard'!$A:$A,0)) -> 87.692721 | F9: =INDEX('KPI Scorecard'!$N:$N,MATCH($B$4,'KPI Scorecard'!$A:$A,0)) -> 0.036655236 | G9: =INDEX($A$13:$A$38,MATCH(MAX($B$13:$B$38),$B$13:$B$38,0)) -> 46368 | H9: =COUNTIF($G$13:$G$38,"Over capacity") -> 6
A11: Next 26 weeks | I11: Forecast pallets per week
A12: Week ending | B12: Forecast pallets | C12: High (P80) | D12: Trailers needed | E12: Contracted | F12: Gap (trailers) | G12: Capacity status
A13: 46235 | B13: =SUMIFS('Volume Forecast'!$E$5:$E$212,'Volume Forecast'!$B$5:$B$212,$B$4,'Volume Forecast'!$A$5:$A$212,$A13) -> 329.3 | C13: =SUMIFS('Volume Forecast'!$G$5:$G$212,'Volume Forecast'!$B$5:$B$212,$B$4,'Volume Forecast'!$A$5:$A$212,$A13) -> 337.4 | D13: =SUMIFS('Volume Forecast'!$J$5:$J$212,'Volume Forecast'!$B$5:$B$212,$B$4,'Volume Forecast'!$A$5:$A$212,$A13) -> 16 | E13: =INDEX('Pool Points'!$I:$I,MATCH($B$4,'Pool Points'!$A:$A,0)) -> 18 | F13: =D13-E13 -> -2 | G13: =IF(D13>E13,"Over capacity",IF(SUMIFS('Volume Forecast'!$K$5:$K$212,'Volume Forecast'!$B$5:$B$212,$B$4,'Volume Forecast'!$A$5:$A$212,$A13)>E13,"At risk","Covered")) -> Covered
A14: 46242 | B14: =SUMIFS('Volume Forecast'!$E$5:$E$212,'Volume Forecast'!$B$5:$B$212,$B$4,'Volume Forecast'!$A$5:$A$212,$A14) -> 331.1 | C14: =SUMIFS('Volume Forecast'!$G$5:$G$212,'Volume Forecast'!$B$5:$B$212,$B$4,'Volume Forecast'!$A$5:$A$212,$A14) -> 339.2 | D14: =SUMIFS('Volume Forecast'!$J$5:$J$212,'Volume Forecast'!$B$5:$B$212,$B$4,'Volume Forecast'!$A$5:$A$212,$A14) -> 16 | E14: =INDEX('Pool Points'!$I:$I,MATCH($B$4,'Pool Points'!$A:$A,0)) -> 18 | F14: =D14-E14 -> -2 | G14: =IF(D14>E14,"Over capacity",IF(SUMIFS('Volume Forecast'!$K$5:$K$212,'Volume Forecast'!$B$5:$B$212,$B$4,'Volume Forecast'!$A$5:$A$212,$A14)>E14,"At risk","Covered")) -> Covered
A15: 46249 | B15: =SUMIFS('Volume Forecast'!$E$5:$E$212,'Volume Forecast'!$B$5:$B$212,$B$4,'Volume Forecast'!$A$5:$A$212,$A15) -> 328.7 | C15: =SUMIFS('Volume Forecast'!$G$5:$G$212,'Volume Forecast'!$B$5:$B$212,$B$4,'Volume Forecast'!$A$5:$A$212,$A15) -> 336.8 | D15: =SUMIFS('Volume Forecast'!$J$5:$J$212,'Volume Forecast'!$B$5:$B$212,$B$4,'Volume Forecast'!$A$5:$A$212,$A15) -> 16 | E15: =INDEX('Pool Points'!$I:$I,MATCH($B$4,'Pool Points'!$A:$A,0)) -> 18 | F15: =D15-E15 -> -2 | G15: =IF(D15>E15,"Over capacity",IF(SUMIFS('Volume Forecast'!$K$5:$K$212,'Volume Forecast'!$B$5:$B$212,$B$4,'Volume Forecast'!$A$5:$A$212,$A15)>E15,"At risk","Covered")) -> Covered
A16: 46256 | B16: =SUMIFS('Volume Forecast'!$E$5:$E$212,'Volume Forecast'!$B$5:$B$212,$B$4,'Volume Forecast'!$A$5:$A$212,$A16) -> 321.2 | C16: =SUMIFS('Volume Forecast'!$G$5:$G$212,'Volume Forecast'!$B$5:$B$212,$B$4,'Volume Forecast'!$A$5:$A$212,$A16) -> 329.1 | D16: =SUMIFS('Volume Forecast'!$J$5:$J$212,'Volume Forecast'!$B$5:$B$212,$B$4,'Volume Forecast'!$A$5:$A$212,$A16) -> 16 | E16: =INDEX('Pool Points'!$I:$I,MATCH($B$4,'Pool Points'!$A:$A,0)) -> 18 | F16: =D16-E16 -> -2 | G16: =IF(D16>E16,"Over capacity",IF(SUMIFS('Volume Forecast'!$K$5:$K$212,'Volume Forecast'!$B$5:$B$212,$B$4,'Volume Forecast'!$A$5:$A$212,$A16)>E16,"At risk","Covered")) -> Covered
A17: 46263 | B17: =SUMIFS('Volume Forecast'!$E$5:$E$212,'Volume Forecast'!$B$5:$B$212,$B$4,'Volume Forecast'!$A$5:$A$212,$A17) -> 313.6 | C17: =SUMIFS('Volume Forecast'!$G$5:$G$212,'Volume Forecast'!$B$5:$B$212,$B$4,'Volume Forecast'!$A$5:$A$212,$A17) -> 321.3 | D17: =SUMIFS('Volume Forecast'!$J$5:$J$212,'Volume Forecast'!$B$5:$B$212,$B$4,'Volume Forecast'!$A$5:$A$212,$A17) -> 15 | E17: =INDEX('Pool Points'!$I:$I,MATCH($B$4,'Pool Points'!$A:$A,0)) -> 18 | F17: =D17-E17 -> -3 | G17: =IF(D17>E17,"Over capacity",IF(SUMIFS('Volume Forecast'!$K$5:$K$212,'Volume Forecast'!$B$5:$B$212,$B$4,'Volume Forecast'!$A$5:$A$212,$A17)>E17,"At risk","Covered")) -> Covered
A18: 46270 | B18: =SUMIFS('Volume Forecast'!$E$5:$E$212,'Volume Forecast'!$B$5:$B$212,$B$4,'Volume Forecast'!$A$5:$A$212,$A18) -> 296 | C18: =SUMIFS('Volume Forecast'!$G$5:$G$212,'Volume Forecast'!$B$5:$B$212,$B$4,'Volume Forecast'!$A$5:$A$212,$A18) -> 303.3 | D18: =SUMIFS('Volume Forecast'!$J$5:$J$212,'Volume Forecast'!$B$5:$B$212,$B$4,'Volume Forecast'!$A$5:$A$212,$A18) -> 15 | E18: =INDEX('Pool Points'!$I:$I,MATCH($B$4,'Pool Points'!$A:$A,0)) -> 18 | F18: =D18-E18 -> -3 | G18: =IF(D18>E18,"Over capacity",IF(SUMIFS('Volume Forecast'!$K$5:$K$212,'Volume Forecast'!$B$5:$B$212,$B$4,'Volume Forecast'!$A$5:$A$212,$A18)>E18,"At risk","Covered")) -> Covered
A19: 46277 | B19: =SUMIFS('Volume Forecast'!$E$5:$E$212,'Volume Forecast'!$B$5:$B$212,$B$4,'Volume Forecast'!$A$5:$A$212,$A19) -> 287.9 | C19: =SUMIFS('Volume Forecast'!$G$5:$G$212,'Volume Forecast'!$B$5:$B$212,$B$4,'Volume Forecast'!$A$5:$A$212,$A19) -> 295 | D19: =SUMIFS('Volume Forecast'!$J$5:$J$212,'Volume Forecast'!$B$5:$B$212,$B$4,'Volume Forecast'!$A$5:$A$212,$A19) -> 14 | E19: =INDEX('Pool Points'!$I:$I,MATCH($B$4,'Pool Points'!$A:$A,0)) -> 18 | F19: =D19-E19 -> -4 | G19: =IF(D19>E19,"Over capacity",IF(SUMIFS('Volume Forecast'!$K$5:$K$212,'Volume Forecast'!$B$5:$B$212,$B$4,'Volume Forecast'!$A$5:$A$212,$A19)>E19,"At risk","Covered")) -> Covered
A20: 46284 | B20: =SUMIFS('Volume Forecast'!$E$5:$E$212,'Volume Forecast'!$B$5:$B$212,$B$4,'Volume Forecast'!$A$5:$A$212,$A20) -> 305.4 | C20: =SUMIFS('Volume Forecast'!$G$5:$G$212,'Volume Forecast'!$B$5:$B$212,$B$4,'Volume Forecast'!$A$5:$A$212,$A20) -> 312.9 | D20: =SUMIFS('Volume Forecast'!$J$5:$J$212,'Volume Forecast'!$B$5:$B$212,$B$4,'Volume Forecast'!$A$5:$A$212,$A20) -> 15 | E20: =INDEX('Pool Points'!$I:$I,MATCH($B$4,'Pool Points'!$A:$A,0)) -> 18 | F20: =D20-E20 -> -3 | G20: =IF(D20>E20,"Over capacity",IF(SUMIFS('Volume Forecast'!$K$5:$K$212,'Volume Forecast'!$B$5:$B$212,$B$4,'Volume Forecast'!$A$5:$A$212,$A20)>E20,"At risk","Covered")) -> Covered
A21: 46291 | B21: =SUMIFS('Volume Forecast'!$E$5:$E$212,'Volume Forecast'!$B$5:$B$212,$B$4,'Volume Forecast'!$A$5:$A$212,$A21) -> 303.5 | C21: =SUMIFS('Volume Forecast'!$G$5:$G$212,'Volume Forecast'!$B$5:$B$212,$B$4,'Volume Forecast'!$A$5:$A$212,$A21) -> 311 | D21: =SUMIFS('Volume Forecast'!$J$5:$J$212,'Volume Forecast'!$B$5:$B$212,$B$4,'Volume Forecast'!$A$5:$A$212,$A21) -> 15 | E21: =INDEX('Pool Points'!$I:$I,MATCH($B$4,'Pool Points'!$A:$A,0)) -> 18 | F21: =D21-E21 -> -3 | G21: =IF(D21>E21,"Over capacity",IF(SUMIFS('Volume Forecast'!$K$5:$K$212,'Volume Forecast'!$B$5:$B$212,$B$4,'Volume Forecast'!$A$5:$A$212,$A21)>E21,"At risk","Covered")) -> Covered
A22: 46298 | B22: =SUMIFS('Volume Forecast'!$E$5:$E$212,'Volume Forecast'!$B$5:$B$212,$B$4,'Volume Forecast'!$A$5:$A$212,$A22) -> 298.5 | C22: =SUMIFS('Volume Forecast'!$G$5:$G$212,'Volume Forecast'!$B$5:$B$212,$B$4,'Volume Forecast'!$A$5:$A$212,$A22) -> 305.8 | D22: =SUMIFS('Volume Forecast'!$J$5:$J$212,'Volume Forecast'!$B$5:$B$212,$B$4,'Volume Forecast'!$A$5:$A$212,$A22) -> 15 | E22: =INDEX('Pool Points'!$I:$I,MATCH($B$4,'Pool Points'!$A:$A,0)) -> 18 | F22: =D22-E22 -> -3 | G22: =IF(D22>E22,"Over capacity",IF(SUMIFS('Volume Forecast'!$K$5:$K$212,'Volume Forecast'!$B$5:$B$212,$B$4,'Volume Forecast'!$A$5:$A$212,$A22)>E22,"At risk","Covered")) -> Covered
A23: 46305 | B23: =SUMIFS('Volume Forecast'!$E$5:$E$212,'Volume Forecast'!$B$5:$B$212,$B$4,'Volume Forecast'!$A$5:$A$212,$A23) -> 311.1 | C23: =SUMIFS('Volume Forecast'!$G$5:$G$212,'Volume Forecast'!$B$5:$B$212,$B$4,'Volume Forecast'!$A$5:$A$212,$A23) -> 318.8 | D23: =SUMIFS('Volume Forecast'!$J$5:$J$212,'Volume Forecast'!$B$5:$B$212,$B$4,'Volume Forecast'!$A$5:$A$212,$A23) -> 15 | E23: =INDEX('Pool Points'!$I:$I,MATCH($B$4,'Pool Points'!$A:$A,0)) -> 18 | F23: =D23-E23 -> -3 | G23: =IF(D23>E23,"Over capacity",IF(SUMIFS('Volume Forecast'!$K$5:$K$212,'Volume Forecast'!$B$5:$B$212,$B$4,'Volume Forecast'!$A$5:$A$212,$A23)>E23,"At risk","Covered")) -> Covered
A24: 46312 | B24: =SUMIFS('Volume Forecast'!$E$5:$E$212,'Volume Forecast'!$B$5:$B$212,$B$4,'Volume Forecast'!$A$5:$A$212,$A24) -> 319.3 | C24: =SUMIFS('Volume Forecast'!$G$5:$G$212,'Volume Forecast'!$B$5:$B$212,$B$4,'Volume Forecast'!$A$5:$A$212,$A24) -> 327.1 | D24: =SUMIFS('Volume Forecast'!$J$5:$J$212,'Volume Forecast'!$B$5:$B$212,$B$4,'Volume Forecast'!$A$5:$A$212,$A24) -> 16 | E24: =INDEX('Pool Points'!$I:$I,MATCH($B$4,'Pool Points'!$A:$A,0)) -> 18 | F24: =D24-E24 -> -2 | G24: =IF(D24>E24,"Over capacity",IF(SUMIFS('Volume Forecast'!$K$5:$K$212,'Volume Forecast'!$B$5:$B$212,$B$4,'Volume Forecast'!$A$5:$A$212,$A24)>E24,"At risk","Covered")) -> Covered
... A26: 46326 | B26: =SUMIFS('Volume Forecast'!$E$5:$E$212,'Volume Forecast'!$B$5:$B$212,$B$4,'Volume Forecast'!$A$5:$A$212,$A26) -> 358.1 | C26: =SUMIFS('Volume Forecast'!$G$5:$G$212,'Volume Forecast'!$B$5:$B$212,$B$4,'Volume Forecast'!$A$5:$A$212,$A26) -> 366.9 | D26: =SUMIFS('Volume Forecast'!$J$5:$J$212,'Volume Forecast'!$B$5:$B$212,$B$4,'Volume Forecast'!$A$5:$A$212,$A26) -> 18 | E26: =INDEX('Pool Points'!$I:$I,MATCH($B$4,'Pool Points'!$A:$A,0)) -> 18 | F26: =D26-E26 -> 0 | G26: =IF(D26>E26,"Over capacity",IF(SUMIFS('Volume Forecast'!$K$5:$K$212,'Volume Forecast'!$B$5:$B$212,$B$4,'Volume Forecast'!$A$5:$A$212,$A26)>E26,"At risk","Covered")) -> Covered
A27: 46333 | B27: =SUMIFS('Volume Forecast'!$E$5:$E$212,'Volume Forecast'!$B$5:$B$212,$B$4,'Volume Forecast'!$A$5:$A$212,$A27) -> 364.1 | C27: =SUMIFS('Volume Forecast'!$G$5:$G$212,'Volume Forecast'!$B$5:$B$212,$B$4,'Volume Forecast'!$A$5:$A$212,$A27) -> 373.1 | D27: =SUMIFS('Volume Forecast'!$J$5:$J$212,'Volume Forecast'!$B$5:$B$212,$B$4,'Volume Forecast'!$A$5:$A$212,$A27) -> 18 | E27: =INDEX('Pool Points'!$I:$I,MATCH($B$4,'Pool Points'!$A:$A,0)) -> 18 | F27: =D27-E27 -> 0 | G27: =IF(D27>E27,"Over capacity",IF(SUMIFS('Volume Forecast'!$K$5:$K$212,'Volume Forecast'!$B$5:$B$212,$B$4,'Volume Forecast'!$A$5:$A$212,$A27)>E27,"At risk","Covered")) -> Covered | I27: Trailers needed vs. contracted per week
A28: 46340 | B28: =SUMIFS('Volume Forecast'!$E$5:$E$212,'Volume Forecast'!$B$5:$B$212,$B$4,'Volume Forecast'!$A$5:$A$212,$A28) -> 398.8 | C28: =SUMIFS('Volume Forecast'!$G$5:$G$212,'Volume Forecast'!$B$5:$B$212,$B$4,'Volume Forecast'!$A$5:$A$212,$A28) -> 408.7 | D28: =SUMIFS('Volume Forecast'!$J$5:$J$212,'Volume Forecast'!$B$5:$B$212,$B$4,'Volume Forecast'!$A$5:$A$212,$A28) -> 20 | E28: =INDEX('Pool Points'!$I:$I,MATCH($B$4,'Pool Points'!$A:$A,0)) -> 18 | F28: =D28-E28 -> 2 | G28: =IF(D28>E28,"Over capacity",IF(SUMIFS('Volume Forecast'!$K$5:$K$212,'Volume Forecast'!$B$5:$B$212,$B$4,'Volume Forecast'!$A$5:$A$212,$A28)>E28,"At risk","Covered")) -> Over capacity
A29: 46347 | B29: =SUMIFS('Volume Forecast'!$E$5:$E$212,'Volume Forecast'!$B$5:$B$212,$B$4,'Volume Forecast'!$A$5:$A$212,$A29) -> 415.7 | C29: =SUMIFS('Volume Forecast'!$G$5:$G$212,'Volume Forecast'!$B$5:$B$212,$B$4,'Volume Forecast'!$A$5:$A$212,$A29) -> 426 | D29: =SUMIFS('Volume Forecast'!$J$5:$J$212,'Volume Forecast'!$B$5:$B$212,$B$4,'Volume Forecast'!$A$5:$A$212,$A29) -> 20 | E29: =INDEX('Pool Points'!$I:$I,MATCH($B$4,'Pool Points'!$A:$A,0)) -> 18 | F29: =D29-E29 -> 2 | G29: =IF(D29>E29,"Over capacity",IF(SUMIFS('Volume Forecast'!$K$5:$K$212,'Volume Forecast'!$B$5:$B$212,$B$4,'Volume Forecast'!$A$5:$A$212,$A29)>E29,"At risk","Covered")) -> Over capacity
A30: 46354 | B30: =SUMIFS('Volume Forecast'!$E$5:$E$212,'Volume Forecast'!$B$5:$B$212,$B$4,'Volume Forecast'!$A$5:$A$212,$A30) -> 445.8 | C30: =SUMIFS('Volume Forecast'!$G$5:$G$212,'Volume Forecast'!$B$5:$B$212,$B$4,'Volume Forecast'!$A$5:$A$212,$A30) -> 456.7 | D30: =SUMIFS('Volume Forecast'!$J$5:$J$212,'Volume Forecast'!$B$5:$B$212,$B$4,'Volume Forecast'!$A$5:$A$212,$A30) -> 22 | E30: =INDEX('Pool Points'!$I:$I,MATCH($B$4,'Pool Points'!$A:$A,0)) -> 18 | F30: =D30-E30 -> 4 | G30: =IF(D30>E30,"Over capacity",IF(SUMIFS('Volume Forecast'!$K$5:$K$212,'Volume Forecast'!$B$5:$B$212,$B$4,'Volume Forecast'!$A$5:$A$212,$A30)>E30,"At risk","Covered")) -> Over capacity
A31: 46361 | B31: =SUMIFS('Volume Forecast'!$E$5:$E$212,'Volume Forecast'!$B$5:$B$212,$B$4,'Volume Forecast'!$A$5:$A$212,$A31) -> 479.2 | C31: =SUMIFS('Volume Forecast'!$G$5:$G$212,'Volume Forecast'!$B$5:$B$212,$B$4,'Volume Forecast'!$A$5:$A$212,$A31) -> 491.1 | D31: =SUMIFS('Volume Forecast'!$J$5:$J$212,'Volume Forecast'!$B$5:$B$212,$B$4,'Volume Forecast'!$A$5:$A$212,$A31) -> 23 | E31: =INDEX('Pool Points'!$I:$I,MATCH($B$4,'Pool Points'!$A:$A,0)) -> 18 | F31: =D31-E31 -> 5 | G31: =IF(D31>E31,"Over capacity",IF(SUMIFS('Volume Forecast'!$K$5:$K$212,'Volume Forecast'!$B$5:$B$212,$B$4,'Volume Forecast'!$A$5:$A$212,$A31)>E31,"At risk","Covered")) -> Over capacity
A32: 46368 | B32: =SUMIFS('Volume Forecast'!$E$5:$E$212,'Volume Forecast'!$B$5:$B$212,$B$4,'Volume Forecast'!$A$5:$A$212,$A32) -> 479.6 | C32: =SUMIFS('Volume Forecast'!$G$5:$G$212,'Volume Forecast'!$B$5:$B$212,$B$4,'Volume Forecast'!$A$5:$A$212,$A32) -> 491.5 | D32: =SUMIFS('Volume Forecast'!$J$5:$J$212,'Volume Forecast'!$B$5:$B$212,$B$4,'Volume Forecast'!$A$5:$A$212,$A32) -> 23 | E32: =INDEX('Pool Points'!$I:$I,MATCH($B$4,'Pool Points'!$A:$A,0)) -> 18 | F32: =D32-E32 -> 5 | G32: =IF(D32>E32,"Over capacity",IF(SUMIFS('Volume Forecast'!$K$5:$K$212,'Volume Forecast'!$B$5:$B$212,$B$4,'Volume Forecast'!$A$5:$A$212,$A32)>E32,"At risk","Covered")) -> Over capacity
A33: 46375 | B33: =SUMIFS('Volume Forecast'!$E$5:$E$212,'Volume Forecast'!$B$5:$B$212,$B$4,'Volume Forecast'!$A$5:$A$212,$A33) -> 422.1 | C33: =SUMIFS('Volume Forecast'!$G$5:$G$212,'Volume Forecast'!$B$5:$B$212,$B$4,'Volume Forecast'!$A$5:$A$212,$A33) -> 432.5 | D33: =SUMIFS('Volume Forecast'!$J$5:$J$212,'Volume Forecast'!$B$5:$B$212,$B$4,'Volume Forecast'!$A$5:$A$212,$A33) -> 21 | E33: =INDEX('Pool Points'!$I:$I,MATCH($B$4,'Pool Points'!$A:$A,0)) -> 18 | F33: =D33-E33 -> 3 | G33: =IF(D33>E33,"Over capacity",IF(SUMIFS('Volume Forecast'!$K$5:$K$212,'Volume Forecast'!$B$5:$B$212,$B$4,'Volume Forecast'!$A$5:$A$212,$A33)>E33,"At risk","Covered")) -> Over capacity
A34: 46382 | B34: =SUMIFS('Volume Forecast'!$E$5:$E$212,'Volume Forecast'!$B$5:$B$212,$B$4,'Volume Forecast'!$A$5:$A$212,$A34) -> 366.6 | C34: =SUMIFS('Volume Forecast'!$G$5:$G$212,'Volume Forecast'!$B$5:$B$212,$B$4,'Volume Forecast'!$A$5:$A$212,$A34) -> 375.6 | D34: =SUMIFS('Volume Forecast'!$J$5:$J$212,'Volume Forecast'!$B$5:$B$212,$B$4,'Volume Forecast'!$A$5:$A$212,$A34) -> 18 | E34: =INDEX('Pool Points'!$I:$I,MATCH($B$4,'Pool Points'!$A:$A,0)) -> 18 | F34: =D34-E34 -> 0 | G34: =IF(D34>E34,"Over capacity",IF(SUMIFS('Volume Forecast'!$K$5:$K$212,'Volume Forecast'!$B$5:$B$212,$B$4,'Volume Forecast'!$A$5:$A$212,$A34)>E34,"At risk","Covered")) -> Covered
A35: 46389 | B35: =SUMIFS('Volume Forecast'!$E$5:$E$212,'Volume Forecast'!$B$5:$B$212,$B$4,'Volume Forecast'!$A$5:$A$212,$A35) -> 310.6 | C35: =SUMIFS('Volume Forecast'!$G$5:$G$212,'Volume Forecast'!$B$5:$B$212,$B$4,'Volume Forecast'!$A$5:$A$212,$A35) -> 318.2 | D35: =SUMIFS('Volume Forecast'!$J$5:$J$212,'Volume Forecast'!$B$5:$B$212,$B$4,'Volume Forecast'!$A$5:$A$212,$A35) -> 15 | E35: =INDEX('Pool Points'!$I:$I,MATCH($B$4,'Pool Points'!$A:$A,0)) -> 18 | F35: =D35-E35 -> -3 | G35: =IF(D35>E35,"Over capacity",IF(SUMIFS('Volume Forecast'!$K$5:$K$212,'Volume Forecast'!$B$5:$B$212,$B$4,'Volume Forecast'!$A$5:$A$212,$A35)>E35,"At risk","Covered")) -> Covered
A36: 46396 | B36: =SUMIFS('Volume Forecast'!$E$5:$E$212,'Volume Forecast'!$B$5:$B$212,$B$4,'Volume Forecast'!$A$5:$A$212,$A36) -> 250.6 | C36: =SUMIFS('Volume Forecast'!$G$5:$G$212,'Volume Forecast'!$B$5:$B$212,$B$4,'Volume Forecast'!$A$5:$A$212,$A36) -> 256.8 | D36: =SUMIFS('Volume Forecast'!$J$5:$J$212,'Volume Forecast'!$B$5:$B$212,$B$4,'Volume Forecast'!$A$5:$A$212,$A36) -> 12 | E36: =INDEX('Pool Points'!$I:$I,MATCH($B$4,'Pool Points'!$A:$A,0)) -> 18 | F36: =D36-E36 -> -6 | G36: =IF(D36>E36,"Over capacity",IF(SUMIFS('Volume Forecast'!$K$5:$K$212,'Volume Forecast'!$B$5:$B$212,$B$4,'Volume Forecast'!$A$5:$A$212,$A36)>E36,"At risk","Covered")) -> Covered
A37: 46403 | B37: =SUMIFS('Volume Forecast'!$E$5:$E$212,'Volume Forecast'!$B$5:$B$212,$B$4,'Volume Forecast'!$A$5:$A$212,$A37) -> 250.6 | C37: =SUMIFS('Volume Forecast'!$G$5:$G$212,'Volume Forecast'!$B$5:$B$212,$B$4,'Volume Forecast'!$A$5:$A$212,$A37) -> 256.8 | D37: =SUMIFS('Volume Forecast'!$J$5:$J$212,'Volume Forecast'!$B$5:$B$212,$B$4,'Volume Forecast'!$A$5:$A$212,$A37) -> 12 | E37: =INDEX('Pool Points'!$I:$I,MATCH($B$4,'Pool Points'!$A:$A,0)) -> 18 | F37: =D37-E37 -> -6 | G37: =IF(D37>E37,"Over capacity",IF(SUMIFS('Volume Forecast'!$K$5:$K$212,'Volume Forecast'!$B$5:$B$212,$B$4,'Volume Forecast'!$A$5:$A$212,$A37)>E37,"At risk","Covered")) -> Covered
A38: 46410 | B38: =SUMIFS('Volume Forecast'!$E$5:$E$212,'Volume Forecast'!$B$5:$B$212,$B$4,'Volume Forecast'!$A$5:$A$212,$A38) -> 262.3 | C38: =SUMIFS('Volume Forecast'!$G$5:$G$212,'Volume Forecast'!$B$5:$B$212,$B$4,'Volume Forecast'!$A$5:$A$212,$A38) -> 268.8 | D38: =SUMIFS('Volume Forecast'!$J$5:$J$212,'Volume Forecast'!$B$5:$B$212,$B$4,'Volume Forecast'!$A$5:$A$212,$A38) -> 13 | E38: =INDEX('Pool Points'!$I:$I,MATCH($B$4,'Pool Points'!$A:$A,0)) -> 18 | F38: =D38-E38 -> -5 | G38: =IF(D38>E38,"Over capacity",IF(SUMIFS('Volume Forecast'!$K$5:$K$212,'Volume Forecast'!$B$5:$B$212,$B$4,'Volume Forecast'!$A$5:$A$212,$A38)>E38,"At risk","Covered")) -> Covered

Sheet KPI Scorecard
A1: KPI Scorecard, trailing 52 weeks
A2: Status columns are formulas against the targets on the Settings sheet.
A3: Targets: | B3: ="On-time "&TEXT(TargetOnTime,"0%")&" Fill "&TEXT(TargetFill,"0%")&" Cost alert "&TEXT(CostIndexAlert,"0.00")&"x network" -> On-time 95% Fill 75% Cost alert 1.10x network
A5: Pool point | B5: City | C5: Carrier | D5: Avg weekly pallets | E5: YoY volume growth | F5: On-time % | G5: On-time status | H5: Trailer fill % | I5: Fill status | J5: Cost per pallet | K5: Cost vs network | L5: Cost status | M5: Avg backlog pallets | N5: Forecast WAPE
A6: PP01 | B6: Albany | C6: CARR-A | D6: 241.80769 | E6: 0.075344223 | F6: 0.95274725 | G6: =IF(F6>=TargetOnTime,"Meets","Below target") -> Meets | H6: 0.7383441 | I6: =IF(H6>=TargetFill,"Meets","Below target") -> Below target | J6: 80.278094 | K6: 0.97794605 | L6: =IF(K6>CostIndexAlert,"High cost","In range") -> In range | M6: 9.6730769 | N6: 0.038798994
A7: PP02 | B7: Hartford | C7: CARR-A | D7: 239.46154 | E7: 0.066552463 | F7: 0.96064401 | G7: =IF(F7>=TargetOnTime,"Meets","Below target") -> Meets | H7: 0.79160839 | I7: =IF(H7>=TargetFill,"Meets","Below target") -> Meets | J7: 84.089745 | K7: 1.0243795 | L7: =IF(K7>CostIndexAlert,"High cost","In range") -> In range | M7: 7.7115385 | N7: 0.028146819
A8: PP03 | B8: Worcester | C8: CARR-B | D8: 323.90385 | E8: 0.06224773 | F8: 0.92548077 | G8: =IF(F8>=TargetOnTime,"Meets","Below target") -> Below target | H8: 0.80473005 | I8: =IF(H8>=TargetFill,"Meets","Below target") -> Meets | J8: 87.692721 | K8: 1.0682709 | L8: =IF(K8>CostIndexAlert,"High cost","In range") -> In range | M8: 14.538462 | N8: 0.036655236
A9: PP04 | B9: Harrisburg | C9: CARR-C | D9: 230.17308 | E9: 0.084541501 | F9: 0.97216599 | G9: =IF(F9>=TargetOnTime,"Meets","Below target") -> Meets | H9: 0.74489669 | I9: =IF(H9>=TargetFill,"Meets","Below target") -> Below target | J9: 68.83121 | K9: 0.83850035 | L9: =IF(K9>CostIndexAlert,"High cost","In range") -> In range | M9: 8.4038462 | N9: 0.031001689
A10: PP05 | B10: Pittsburgh | C10: CARR-C | D10: 301.34615 | E10: 0.060718879 | F10: 0.96645796 | G10: =IF(F10>=TargetOnTime,"Meets","Below target") -> Meets | H10: 0.78373512 | I10: =IF(H10>=TargetFill,"Meets","Below target") -> Meets | J10: 95.341895 | K10: 1.161453 | L10: =IF(K10>CostIndexAlert,"High cost","In range") -> High cost | M10: 16.769231 | N10: 0.039016944
A11: PP06 | B11: Baltimore | C11: CARR-D | D11: 280.25 | E11: 0.097777778 | F11: 0.95403377 | G11: =IF(F11>=TargetOnTime,"Meets","Below target") -> Meets | H11: 0.76886145 | I11: =IF(H11>=TargetFill,"Meets","Below target") -> Meets | J11: 65.329033 | K11: 0.79583691 | L11: =IF(K11>CostIndexAlert,"High cost","In range") -> In range | M11: 11.115385 | N11: 0.046718156
A12: PP07 | B12: Richmond | C12: CARR-D | D12: 227.36538 | E12: 0.090883927 | F12: 0.9475052 | G12: =IF(F12>=TargetOnTime,"Meets","Below target") -> Below target | H12: 0.75662358 | I12: =IF(H12>=TargetFill,"Meets","Below target") -> Meets | J12: 85.179544 | K12: 1.0376554 | L12: =IF(K12>CostIndexAlert,"High cost","In range") -> In range | M12: 7 | N12: 0.033816745
A13: PP08 | B13: Syracuse | C13: CARR-B | D13: 217.53846 | E13: 0.060268066 | F13: 0.91813187 | G13: =IF(F13>=TargetOnTime,"Meets","Below target") -> Below target | H13: 0.70060696 | I13: =IF(H13>=TargetFill,"Meets","Below target") -> Below target | J13: 87.581374 | K13: 1.0669145 | L13: =IF(K13>CostIndexAlert,"High cost","In range") -> In range | M13: 8.5192308 | N13: 0.024209754
A15: Carrier scorecard
A16: Carrier | B16: Name | C16: Lanes | D16: Avg weekly pallets | E16: On-time % | F16: On-time status | G16: Trailer fill % | H16: Cost per pallet
A17: CARR-A | B17: Carrier A | C17: 2 | D17: 481.26923 | E17: 0.95710059 | F17: =IF(E17>=TargetOnTime,"Meets","Below target") -> Meets | G17: 0.76391941 | H17: 82.174628
A18: CARR-B | B18: Carrier B | C18: 2 | D18: 541.44231 | E18: 0.92238184 | F18: =IF(E18>=TargetOnTime,"Meets","Below target") -> Below target | G18: 0.75938613 | H18: 87.647984
A19: CARR-C | B19: Carrier C | C19: 2 | D19: 531.51923 | E19: 0.9691358 | F19: =IF(E19>=TargetOnTime,"Meets","Below target") -> Meets | G19: 0.76643004 | H19: 83.861509
A20: CARR-D | B20: Carrier D | C20: 2 | D20: 507.61538 | E20: 0.95093688 | F20: =IF(E20>=TargetOnTime,"Meets","Below target") -> Meets | G20: 0.76333141 | H20: 74.220251

Sheet Volume Forecast
A1: Volume Forecast by Lane
A2: Columns I to N are formulas: trailers = pallets / (pallets per trailer x lane fill rate), rounded up.
A4: Week ending | B4: Pool point | C4: City | D4: Carrier | E4: Forecast pallets | F4: Low (P10) | G4: High (P80) | H4: New store pallets | I4: Lane fill rate | J4: Trailers (forecast) | K4: Trailers (high) | L4: Contracted trailers | M4: Extra trailers needed | N4: Capacity status
A5: 46235 | B5: PP01 | C5: Albany | D5: CARR-A | E5: 240.5 | F5: 225.9 | G5: 246.5 | H5: 0 | I5: =INDEX('Pool Points'!$J:$J,MATCH(B5,'Pool Points'!$A:$A,0)) -> 0.7383 | J5: =ROUNDUP(E5/(PalletsPerTrailer*I5),0) -> 13 | K5: =ROUNDUP(G5/(PalletsPerTrailer*I5),0) -> 13 | L5: =INDEX('Pool Points'!$I:$I,MATCH(B5,'Pool Points'!$A:$A,0)) -> 15 | M5: =MAX(0,K5-L5) -> 0 | N5: =IF(J5>L5,"Over capacity",IF(K5>L5,"At risk","Covered")) -> Covered
A6: 46235 | B6: PP02 | C6: Hartford | D6: CARR-A | E6: 249.5 | F6: 234.3 | G6: 255.6 | H6: 0 | I6: =INDEX('Pool Points'!$J:$J,MATCH(B6,'Pool Points'!$A:$A,0)) -> 0.7916 | J6: =ROUNDUP(E6/(PalletsPerTrailer*I6),0) -> 13 | K6: =ROUNDUP(G6/(PalletsPerTrailer*I6),0) -> 13 | L6: =INDEX('Pool Points'!$I:$I,MATCH(B6,'Pool Points'!$A:$A,0)) -> 15 | M6: =MAX(0,K6-L6) -> 0 | N6: =IF(J6>L6,"Over capacity",IF(K6>L6,"At risk","Covered")) -> Covered
A7: 46235 | B7: PP03 | C7: Worcester | D7: CARR-B | E7: 329.3 | F7: 309.3 | G7: 337.4 | H7: 0 | I7: =INDEX('Pool Points'!$J:$J,MATCH(B7,'Pool Points'!$A:$A,0)) -> 0.8047 | J7: =ROUNDUP(E7/(PalletsPerTrailer*I7),0) -> 16 | K7: =ROUNDUP(G7/(PalletsPerTrailer*I7),0) -> 17 | L7: =INDEX('Pool Points'!$I:$I,MATCH(B7,'Pool Points'!$A:$A,0)) -> 18 | M7: =MAX(0,K7-L7) -> 0 | N7: =IF(J7>L7,"Over capacity",IF(K7>L7,"At risk","Covered")) -> Covered
A8: 46235 | B8: PP04 | C8: Harrisburg | D8: CARR-C | E8: 236.1 | F8: 221.7 | G8: 241.9 | H8: 0 | I8: =INDEX('Pool Points'!$J:$J,MATCH(B8,'Pool Points'!$A:$A,0)) -> 0.7449 | J8: =ROUNDUP(E8/(PalletsPerTrailer*I8),0) -> 13 | K8: =ROUNDUP(G8/(PalletsPerTrailer*I8),0) -> 13 | L8: =INDEX('Pool Points'!$I:$I,MATCH(B8,'Pool Points'!$A:$A,0)) -> 15 | M8: =MAX(0,K8-L8) -> 0 | N8: =IF(J8>L8,"Over capacity",IF(K8>L8,"At risk","Covered")) -> Covered
A9: 46235 | B9: PP05 | C9: Pittsburgh | D9: CARR-C | E9: 314.9 | F9: 295.7 | G9: 322.6 | H9: 0 | I9: =INDEX('Pool Points'!$J:$J,MATCH(B9,'Pool Points'!$A:$A,0)) -> 0.7837 | J9: =ROUNDUP(E9/(PalletsPerTrailer*I9),0) -> 16 | K9: =ROUNDUP(G9/(PalletsPerTrailer*I9),0) -> 16 | L9: =INDEX('Pool Points'!$I:$I,MATCH(B9,'Pool Points'!$A:$A,0)) -> 17 | M9: =MAX(0,K9-L9) -> 0 | N9: =IF(J9>L9,"Over capacity",IF(K9>L9,"At risk","Covered")) -> Covered
A10: 46235 | B10: PP06 | C10: Baltimore | D10: CARR-D | E10: 281.1 | F10: 264 | G10: 288.1 | H10: 0 | I10: =INDEX('Pool Points'!$J:$J,MATCH(B10,'Pool Points'!$A:$A,0)) -> 0.7689 | J10: =ROUNDUP(E10/(PalletsPerTrailer*I10),0) -> 15 | K10: =ROUNDUP(G10/(PalletsPerTrailer*I10),0) -> 15 | L10: =INDEX('Pool Points'!$I:$I,MATCH(B10,'Pool Points'!$A:$A,0)) -> 17 | M10: =MAX(0,K10-L10) -> 0 | N10: =IF(J10>L10,"Over capacity",IF(K10>L10,"At risk","Covered")) -> Covered
A11: 46235 | B11: PP07 | C11: Richmond | D11: CARR-D | E11: 237.9 | F11: 223.4 | G11: 243.7 | H11: 0 | I11: =INDEX('Pool Points'!$J:$J,MATCH(B11,'Pool Points'!$A:$A,0)) -> 0.7566 | J11: =ROUNDUP(E11/(PalletsPerTrailer*I11),0) -> 13 | K11: =ROUNDUP(G11/(PalletsPerTrailer*I11),0) -> 13 | L11: =INDEX('Pool Points'!$I:$I,MATCH(B11,'Pool Points'!$A:$A,0)) -> 13 | M11: =MAX(0,K11-L11) -> 0 | N11: =IF(J11>L11,"Over capacity",IF(K11>L11,"At risk","Covered")) -> Covered
A12: 46235 | B12: PP08 | C12: Syracuse | D12: CARR-B | E12: 228.8 | F12: 214.9 | G12: 234.4 | H12: 0 | I12: =INDEX('Pool Points'!$J:$J,MATCH(B12,'Pool Points'!$A:$A,0)) -> 0.7006 | J12: =ROUNDUP(E12/(PalletsPerTrailer*I12),0) -> 13 | K12: =ROUNDUP(G12/(PalletsPerTrailer*I12),0) -> 13 | L12: =INDEX('Pool Points'!$I:$I,MATCH(B12,'Pool Points'!$A:$A,0)) -> 13 | M12: =MAX(0,K12-L12) -> 0 | N12: =IF(J12>L12,"Over capacity",IF(K12>L12,"At risk","Covered")) -> Covered
A13: 46242 | B13: PP01 | C13: Albany | D13: CARR-A | E13: 253.3 | F13: 237.9 | G13: 259.5 | H13: 0 | I13: =INDEX('Pool Points'!$J:$J,MATCH(B13,'Pool Points'!$A:$A,0)) -> 0.7383 | J13: =ROUNDUP(E13/(PalletsPerTrailer*I13),0) -> 14 | K13: =ROUNDUP(G13/(PalletsPerTrailer*I13),0) -> 14 | L13: =INDEX('Pool Points'!$I:$I,MATCH(B13,'Pool Points'!$A:$A,0)) -> 15 | M13: =MAX(0,K13-L13) -> 0 | N13: =IF(J13>L13,"Over capacity",IF(K13>L13,"At risk","Covered")) -> Covered
A14: 46242 | B14: PP02 | C14: Hartford | D14: CARR-A | E14: 248.2 | F14: 233.1 | G14: 254.4 | H14: 0 | I14: =INDEX('Pool Points'!$J:$J,MATCH(B14,'Pool Points'!$A:$A,0)) -> 0.7916 | J14: =ROUNDUP(E14/(PalletsPerTrailer*I14),0) -> 13 | K14: =ROUNDUP(G14/(PalletsPerTrailer*I14),0) -> 13 | L14: =INDEX('Pool Points'!$I:$I,MATCH(B14,'Pool Points'!$A:$A,0)) -> 15 | M14: =MAX(0,K14-L14) -> 0 | N14: =IF(J14>L14,"Over capacity",IF(K14>L14,"At risk","Covered")) -> Covered
A15: 46242 | B15: PP03 | C15: Worcester | D15: CARR-B | E15: 331.1 | F15: 310.9 | G15: 339.2 | H15: 0 | I15: =INDEX('Pool Points'!$J:$J,MATCH(B15,'Pool Points'!$A:$A,0)) -> 0.8047 | J15: =ROUNDUP(E15/(PalletsPerTrailer*I15),0) -> 16 | K15: =ROUNDUP(G15/(PalletsPerTrailer*I15),0) -> 17 | L15: =INDEX('Pool Points'!$I:$I,MATCH(B15,'Pool Points'!$A:$A,0)) -> 18 | M15: =MAX(0,K15-L15) -> 0 | N15: =IF(J15>L15,"Over capacity",IF(K15>L15,"At risk","Covered")) -> Covered
A16: 46242 | B16: PP04 | C16: Harrisburg | D16: CARR-C | E16: 239.1 | F16: 224.5 | G16: 245 | H16: 0 | I16: =INDEX('Pool Points'!$J:$J,MATCH(B16,'Pool Points'!$A:$A,0)) -> 0.7449 | J16: =ROUNDUP(E16/(PalletsPerTrailer*I16),0) -> 13 | K16: =ROUNDUP(G16/(PalletsPerTrailer*I16),0) -> 13 | L16: =INDEX('Pool Points'!$I:$I,MATCH(B16,'Pool Points'!$A:$A,0)) -> 15 | M16: =MAX(0,K16-L16) -> 0 | N16: =IF(J16>L16,"Over capacity",IF(K16>L16,"At risk","Covered")) -> Covered
... A212: 46410 | B212: PP08 | C212: Syracuse | D212: CARR-B | E212: 184.9 | F212: 173.7 | G212: 189.5 | H212: 0 | I212: =INDEX('Pool Points'!$J:$J,MATCH(B212,'Pool Points'!$A:$A,0)) -> 0.7006 | J212: =ROUNDUP(E212/(PalletsPerTrailer*I212),0) -> 11 | K212: =ROUNDUP(G212/(PalletsPerTrailer*I212),0) -> 11 | L212: =INDEX('Pool Points'!$I:$I,MATCH(B212,'Pool Points'!$A:$A,0)) -> 13 | M212: =MAX(0,K212-L212) -> 0 | N212: =IF(J212>L212,"Over capacity",IF(K212>L212,"At risk","Covered")) -> Covered

Sheet Forecast Matrix
A1: Forecast Matrix
A2: Forecast pallets by pool point and week (SUMIFS over the Volume Forecast sheet).
A4: Pool point | B4: City | C4: 46235 | D4: 46242 | E4: 46249 | F4: 46256 | G4: 46263 | H4: 46270 | I4: 46277 | J4: 46284 | K4: 46291 | L4: 46298 | M4: 46305 | N4: 46312 | O4: 46319 | P4: 46326 | Q4: 46333 | R4: 46340 | S4: 46347 | T4: 46354 | U4: 46361 | V4: 46368 | W4: 46375 | X4: 46382 | Y4: 46389 | Z4: 46396 | AA4: 46403 | AB4: 46410
A5: PP01 | B5: Albany | C5: =SUMIFS('Volume Forecast'!$E$5:$E$212,'Volume Forecast'!$B$5:$B$212,$A5,'Volume Forecast'!$A$5:$A$212,C$4) -> 240.5 | D5: =SUMIFS('Volume Forecast'!$E$5:$E$212,'Volume Forecast'!$B$5:$B$212,$A5,'Volume Forecast'!$A$5:$A$212,D$4) -> 253.3 | E5: =SUMIFS('Volume Forecast'!$E$5:$E$212,'Volume Forecast'!$B$5:$B$212,$A5,'Volume Forecast'!$A$5:$A$212,E$4) -> 236.6 | F5: =SUMIFS('Volume Forecast'!$E$5:$E$212,'Volume Forecast'!$B$5:$B$212,$A5,'Volume Forecast'!$A$5:$A$212,F$4) -> 236 | G5: =SUMIFS('Volume Forecast'!$E$5:$E$212,'Volume Forecast'!$B$5:$B$212,$A5,'Volume Forecast'!$A$5:$A$212,G$4) -> 230.6 | H5: =SUMIFS('Volume Forecast'!$E$5:$E$212,'Volume Forecast'!$B$5:$B$212,$A5,'Volume Forecast'!$A$5:$A$212,H$4) -> 228.7 | I5: =SUMIFS('Volume Forecast'!$E$5:$E$212,'Volume Forecast'!$B$5:$B$212,$A5,'Volume Forecast'!$A$5:$A$212,I$4) -> 226.8 | J5: =SUMIFS('Volume Forecast'!$E$5:$E$212,'Volume Forecast'!$B$5:$B$212,$A5,'Volume Forecast'!$A$5:$A$212,J$4) -> 228.4 | ... AB5: =SUMIFS('Volume Forecast'!$E$5:$E$212,'Volume Forecast'!$B$5:$B$212,$A5,'Volume Forecast'!$A$5:$A$212,AB$4) -> 197
A6: PP02 | B6: Hartford | C6: =SUMIFS('Volume Forecast'!$E$5:$E$212,'Volume Forecast'!$B$5:$B$212,$A6,'Volume Forecast'!$A$5:$A$212,C$4) -> 249.5 | D6: =SUMIFS('Volume Forecast'!$E$5:$E$212,'Volume Forecast'!$B$5:$B$212,$A6,'Volume Forecast'!$A$5:$A$212,D$4) -> 248.2 | E6: =SUMIFS('Volume Forecast'!$E$5:$E$212,'Volume Forecast'!$B$5:$B$212,$A6,'Volume Forecast'!$A$5:$A$212,E$4) -> 246.4 | F6: =SUMIFS('Volume Forecast'!$E$5:$E$212,'Volume Forecast'!$B$5:$B$212,$A6,'Volume Forecast'!$A$5:$A$212,F$4) -> 241.8 | G6: =SUMIFS('Volume Forecast'!$E$5:$E$212,'Volume Forecast'!$B$5:$B$212,$A6,'Volume Forecast'!$A$5:$A$212,G$4) -> 232.7 | H6: =SUMIFS('Volume Forecast'!$E$5:$E$212,'Volume Forecast'!$B$5:$B$212,$A6,'Volume Forecast'!$A$5:$A$212,H$4) -> 231.8 | I6: =SUMIFS('Volume Forecast'!$E$5:$E$212,'Volume Forecast'!$B$5:$B$212,$A6,'Volume Forecast'!$A$5:$A$212,I$4) -> 220.8 | J6: =SUMIFS('Volume Forecast'!$E$5:$E$212,'Volume Forecast'!$B$5:$B$212,$A6,'Volume Forecast'!$A$5:$A$212,J$4) -> 221 | ... AB6: =SUMIFS('Volume Forecast'!$E$5:$E$212,'Volume Forecast'!$B$5:$B$212,$A6,'Volume Forecast'!$A$5:$A$212,AB$4) -> 196.7
A7: PP03 | B7: Worcester | C7: =SUMIFS('Volume Forecast'!$E$5:$E$212,'Volume Forecast'!$B$5:$B$212,$A7,'Volume Forecast'!$A$5:$A$212,C$4) -> 329.3 | D7: =SUMIFS('Volume Forecast'!$E$5:$E$212,'Volume Forecast'!$B$5:$B$212,$A7,'Volume Forecast'!$A$5:$A$212,D$4) -> 331.1 | E7: =SUMIFS('Volume Forecast'!$E$5:$E$212,'Volume Forecast'!$B$5:$B$212,$A7,'Volume Forecast'!$A$5:$A$212,E$4) -> 328.7 | F7: =SUMIFS('Volume Forecast'!$E$5:$E$212,'Volume Forecast'!$B$5:$B$212,$A7,'Volume Forecast'!$A$5:$A$212,F$4) -> 321.2 | G7: =SUMIFS('Volume Forecast'!$E$5:$E$212,'Volume Forecast'!$B$5:$B$212,$A7,'Volume Forecast'!$A$5:$A$212,G$4) -> 313.6 | H7: =SUMIFS('Volume Forecast'!$E$5:$E$212,'Volume Forecast'!$B$5:$B$212,$A7,'Volume Forecast'!$A$5:$A$212,H$4) -> 296 | I7: =SUMIFS('Volume Forecast'!$E$5:$E$212,'Volume Forecast'!$B$5:$B$212,$A7,'Volume Forecast'!$A$5:$A$212,I$4) -> 287.9 | J7: =SUMIFS('Volume Forecast'!$E$5:$E$212,'Volume Forecast'!$B$5:$B$212,$A7,'Volume Forecast'!$A$5:$A$212,J$4) -> 305.4 | ... AB7: =SUMIFS('Volume Forecast'!$E$5:$E$212,'Volume Forecast'!$B$5:$B$212,$A7,'Volume Forecast'!$A$5:$A$212,AB$4) -> 262.3
A8: PP04 | B8: Harrisburg | C8: =SUMIFS('Volume Forecast'!$E$5:$E$212,'Volume Forecast'!$B$5:$B$212,$A8,'Volume Forecast'!$A$5:$A$212,C$4) -> 236.1 | D8: =SUMIFS('Volume Forecast'!$E$5:$E$212,'Volume Forecast'!$B$5:$B$212,$A8,'Volume Forecast'!$A$5:$A$212,D$4) -> 239.1 | E8: =SUMIFS('Volume Forecast'!$E$5:$E$212,'Volume Forecast'!$B$5:$B$212,$A8,'Volume Forecast'!$A$5:$A$212,E$4) -> 236.5 | F8: =SUMIFS('Volume Forecast'!$E$5:$E$212,'Volume Forecast'!$B$5:$B$212,$A8,'Volume Forecast'!$A$5:$A$212,F$4) -> 231.2 | G8: =SUMIFS('Volume Forecast'!$E$5:$E$212,'Volume Forecast'!$B$5:$B$212,$A8,'Volume Forecast'!$A$5:$A$212,G$4) -> 224.4 | H8: =SUMIFS('Volume Forecast'!$E$5:$E$212,'Volume Forecast'!$B$5:$B$212,$A8,'Volume Forecast'!$A$5:$A$212,H$4) -> 217.1 | I8: =SUMIFS('Volume Forecast'!$E$5:$E$212,'Volume Forecast'!$B$5:$B$212,$A8,'Volume Forecast'!$A$5:$A$212,I$4) -> 221.1 | J8: =SUMIFS('Volume Forecast'!$E$5:$E$212,'Volume Forecast'!$B$5:$B$212,$A8,'Volume Forecast'!$A$5:$A$212,J$4) -> 220.4 | ... AB8: =SUMIFS('Volume Forecast'!$E$5:$E$212,'Volume Forecast'!$B$5:$B$212,$A8,'Volume Forecast'!$A$5:$A$212,AB$4) -> 203.5
A9: PP05 | B9: Pittsburgh | C9: =SUMIFS('Volume Forecast'!$E$5:$E$212,'Volume Forecast'!$B$5:$B$212,$A9,'Volume Forecast'!$A$5:$A$212,C$4) -> 314.9 | D9: =SUMIFS('Volume Forecast'!$E$5:$E$212,'Volume Forecast'!$B$5:$B$212,$A9,'Volume Forecast'!$A$5:$A$212,D$4) -> 306.7 | E9: =SUMIFS('Volume Forecast'!$E$5:$E$212,'Volume Forecast'!$B$5:$B$212,$A9,'Volume Forecast'!$A$5:$A$212,E$4) -> 306.2 | F9: =SUMIFS('Volume Forecast'!$E$5:$E$212,'Volume Forecast'!$B$5:$B$212,$A9,'Volume Forecast'!$A$5:$A$212,F$4) -> 296.8 | G9: =SUMIFS('Volume Forecast'!$E$5:$E$212,'Volume Forecast'!$B$5:$B$212,$A9,'Volume Forecast'!$A$5:$A$212,G$4) -> 281.5 | H9: =SUMIFS('Volume Forecast'!$E$5:$E$212,'Volume Forecast'!$B$5:$B$212,$A9,'Volume Forecast'!$A$5:$A$212,H$4) -> 280.8 | I9: =SUMIFS('Volume Forecast'!$E$5:$E$212,'Volume Forecast'!$B$5:$B$212,$A9,'Volume Forecast'!$A$5:$A$212,I$4) -> 277.6 | J9: =SUMIFS('Volume Forecast'!$E$5:$E$212,'Volume Forecast'!$B$5:$B$212,$A9,'Volume Forecast'!$A$5:$A$212,J$4) -> 279.8 | ... AB9: =SUMIFS('Volume Forecast'!$E$5:$E$212,'Volume Forecast'!$B$5:$B$212,$A9,'Volume Forecast'!$A$5:$A$212,AB$4) -> 251.5
A10: PP06 | B10: Baltimore | C10: =SUMIFS('Volume Forecast'!$E$5:$E$212,'Volume Forecast'!$B$5:$B$212,$A10,'Volume Forecast'!$A$5:$A$212,C$4) -> 281.1 | D10: =SUMIFS('Volume Forecast'!$E$5:$E$212,'Volume Forecast'!$B$5:$B$212,$A10,'Volume Forecast'!$A$5:$A$212,D$4) -> 288.3 | E10: =SUMIFS('Volume Forecast'!$E$5:$E$212,'Volume Forecast'!$B$5:$B$212,$A10,'Volume Forecast'!$A$5:$A$212,E$4) -> 289.8 | F10: =SUMIFS('Volume Forecast'!$E$5:$E$212,'Volume Forecast'!$B$5:$B$212,$A10,'Volume Forecast'!$A$5:$A$212,F$4) -> 274.7 | G10: =SUMIFS('Volume Forecast'!$E$5:$E$212,'Volume Forecast'!$B$5:$B$212,$A10,'Volume Forecast'!$A$5:$A$212,G$4) -> 271.8 | H10: =SUMIFS('Volume Forecast'!$E$5:$E$212,'Volume Forecast'!$B$5:$B$212,$A10,'Volume Forecast'!$A$5:$A$212,H$4) -> 261.8 | I10: =SUMIFS('Volume Forecast'!$E$5:$E$212,'Volume Forecast'!$B$5:$B$212,$A10,'Volume Forecast'!$A$5:$A$212,I$4) -> 255.7 | J10: =SUMIFS('Volume Forecast'!$E$5:$E$212,'Volume Forecast'!$B$5:$B$212,$A10,'Volume Forecast'!$A$5:$A$212,J$4) -> 266.7 | ... AB10: =SUMIFS('Volume Forecast'!$E$5:$E$212,'Volume Forecast'!$B$5:$B$212,$A10,'Volume Forecast'!$A$5:$A$212,AB$4) -> 229.9
A11: PP07 | B11: Richmond | C11: =SUMIFS('Volume Forecast'!$E$5:$E$212,'Volume Forecast'!$B$5:$B$212,$A11,'Volume Forecast'!$A$5:$A$212,C$4) -> 237.9 | D11: =SUMIFS('Volume Forecast'!$E$5:$E$212,'Volume Forecast'!$B$5:$B$212,$A11,'Volume Forecast'!$A$5:$A$212,D$4) -> 241.6 | E11: =SUMIFS('Volume Forecast'!$E$5:$E$212,'Volume Forecast'!$B$5:$B$212,$A11,'Volume Forecast'!$A$5:$A$212,E$4) -> 237.3 | F11: =SUMIFS('Volume Forecast'!$E$5:$E$212,'Volume Forecast'!$B$5:$B$212,$A11,'Volume Forecast'!$A$5:$A$212,F$4) -> 230.6 | G11: =SUMIFS('Volume Forecast'!$E$5:$E$212,'Volume Forecast'!$B$5:$B$212,$A11,'Volume Forecast'!$A$5:$A$212,G$4) -> 222.1 | H11: =SUMIFS('Volume Forecast'!$E$5:$E$212,'Volume Forecast'!$B$5:$B$212,$A11,'Volume Forecast'!$A$5:$A$212,H$4) -> 220.9 | I11: =SUMIFS('Volume Forecast'!$E$5:$E$212,'Volume Forecast'!$B$5:$B$212,$A11,'Volume Forecast'!$A$5:$A$212,I$4) -> 219.8 | J11: =SUMIFS('Volume Forecast'!$E$5:$E$212,'Volume Forecast'!$B$5:$B$212,$A11,'Volume Forecast'!$A$5:$A$212,J$4) -> 220 | ... AB11: =SUMIFS('Volume Forecast'!$E$5:$E$212,'Volume Forecast'!$B$5:$B$212,$A11,'Volume Forecast'!$A$5:$A$212,AB$4) -> 207.9
A12: PP08 | B12: Syracuse | C12: =SUMIFS('Volume Forecast'!$E$5:$E$212,'Volume Forecast'!$B$5:$B$212,$A12,'Volume Forecast'!$A$5:$A$212,C$4) -> 228.8 | D12: =SUMIFS('Volume Forecast'!$E$5:$E$212,'Volume Forecast'!$B$5:$B$212,$A12,'Volume Forecast'!$A$5:$A$212,D$4) -> 226.1 | E12: =SUMIFS('Volume Forecast'!$E$5:$E$212,'Volume Forecast'!$B$5:$B$212,$A12,'Volume Forecast'!$A$5:$A$212,E$4) -> 218.8 | F12: =SUMIFS('Volume Forecast'!$E$5:$E$212,'Volume Forecast'!$B$5:$B$212,$A12,'Volume Forecast'!$A$5:$A$212,F$4) -> 221.8 | G12: =SUMIFS('Volume Forecast'!$E$5:$E$212,'Volume Forecast'!$B$5:$B$212,$A12,'Volume Forecast'!$A$5:$A$212,G$4) -> 211.7 | H12: =SUMIFS('Volume Forecast'!$E$5:$E$212,'Volume Forecast'!$B$5:$B$212,$A12,'Volume Forecast'!$A$5:$A$212,H$4) -> 206.3 | I12: =SUMIFS('Volume Forecast'!$E$5:$E$212,'Volume Forecast'!$B$5:$B$212,$A12,'Volume Forecast'!$A$5:$A$212,I$4) -> 202.3 | J12: =SUMIFS('Volume Forecast'!$E$5:$E$212,'Volume Forecast'!$B$5:$B$212,$A12,'Volume Forecast'!$A$5:$A$212,J$4) -> 204.6 | ... AB12: =SUMIFS('Volume Forecast'!$E$5:$E$212,'Volume Forecast'!$B$5:$B$212,$A12,'Volume Forecast'!$A$5:$A$212,AB$4) -> 184.9
A13: Network | C13: =SUM(C5:C12) -> 2118.1 | D13: =SUM(D5:D12) -> 2134.4 | E13: =SUM(E5:E12) -> 2100.3 | F13: =SUM(F5:F12) -> 2054.1 | G13: =SUM(G5:G12) -> 1988.4 | H13: =SUM(H5:H12) -> 1943.4 | I13: =SUM(I5:I12) -> 1912 | J13: =SUM(J5:J12) -> 1946.3 | ... AB13: =SUM(AB5:AB12) -> 1733.7

Sheet Carrier Outlook
A1: Carrier Outlook
A2: Surge trailers to request from each carrier (high case vs. contract). Formulas sum the Volume Forecast sheet.
A4: Summary
A5: Carrier ID | B5: Carrier name | C5: Lanes | D5: Contracted trailers | E5: Avg forecast trailers | F5: Peak trailers high | G5: Surge weeks | H5: Max extra trailers | I5: Peak week
A6: CARR-A | B6: Carrier A | C6: 2 | D6: 30 | E6: 26.769231 | F6: 39 | G6: 6 | H6: 9 | I6: 46361
A7: CARR-B | B7: Carrier B | C7: 2 | D7: 31 | E7: 30.307692 | F7: 43 | G7: 10 | H7: 12 | I7: 46361
A8: CARR-C | B8: Carrier C | C8: 2 | D8: 32 | E8: 30.153846 | F8: 43 | G8: 8 | H8: 11 | I8: 46361
A9: CARR-D | B9: Carrier D | C9: 2 | D9: 30 | E9: 29.038462 | F9: 42 | G9: 10 | H9: 12 | I9: 46361
A11: Extra trailers needed by week (high case)
A12: Carrier | B12: Name | C12: 46235 | D12: 46242 | E12: 46249 | F12: 46256 | G12: 46263 | H12: 46270 | I12: 46277 | J12: 46284 | K12: 46291 | L12: 46298 | M12: 46305 | N12: 46312 | O12: 46319 | P12: 46326 | Q12: 46333 | R12: 46340 | S12: 46347 | T12: 46354 | U12: 46361 | V12: 46368 | W12: 46375 | X12: 46382 | Y12: 46389 | Z12: 46396 | AA12: 46403 | AB12: 46410
A13: CARR-A | B13: Carrier A | C13: =SUMIFS('Volume Forecast'!$M$5:$M$212,'Volume Forecast'!$D$5:$D$212,$A13,'Volume Forecast'!$A$5:$A$212,C$12) -> 0 | D13: =SUMIFS('Volume Forecast'!$M$5:$M$212,'Volume Forecast'!$D$5:$D$212,$A13,'Volume Forecast'!$A$5:$A$212,D$12) -> 0 | E13: =SUMIFS('Volume Forecast'!$M$5:$M$212,'Volume Forecast'!$D$5:$D$212,$A13,'Volume Forecast'!$A$5:$A$212,E$12) -> 0 | F13: =SUMIFS('Volume Forecast'!$M$5:$M$212,'Volume Forecast'!$D$5:$D$212,$A13,'Volume Forecast'!$A$5:$A$212,F$12) -> 0 | G13: =SUMIFS('Volume Forecast'!$M$5:$M$212,'Volume Forecast'!$D$5:$D$212,$A13,'Volume Forecast'!$A$5:$A$212,G$12) -> 0 | H13: =SUMIFS('Volume Forecast'!$M$5:$M$212,'Volume Forecast'!$D$5:$D$212,$A13,'Volume Forecast'!$A$5:$A$212,H$12) -> 0 | I13: =SUMIFS('Volume Forecast'!$M$5:$M$212,'Volume Forecast'!$D$5:$D$212,$A13,'Volume Forecast'!$A$5:$A$212,I$12) -> 0 | J13: =SUMIFS('Volume Forecast'!$M$5:$M$212,'Volume Forecast'!$D$5:$D$212,$A13,'Volume Forecast'!$A$5:$A$212,J$12) -> 0 | ... AB13: =SUMIFS('Volume Forecast'!$M$5:$M$212,'Volume Forecast'!$D$5:$D$212,$A13,'Volume Forecast'!$A$5:$A$212,AB$12) -> 0
A14: CARR-B | B14: Carrier B | C14: =SUMIFS('Volume Forecast'!$M$5:$M$212,'Volume Forecast'!$D$5:$D$212,$A14,'Volume Forecast'!$A$5:$A$212,C$12) -> 0 | D14: =SUMIFS('Volume Forecast'!$M$5:$M$212,'Volume Forecast'!$D$5:$D$212,$A14,'Volume Forecast'!$A$5:$A$212,D$12) -> 0 | E14: =SUMIFS('Volume Forecast'!$M$5:$M$212,'Volume Forecast'!$D$5:$D$212,$A14,'Volume Forecast'!$A$5:$A$212,E$12) -> 0 | F14: =SUMIFS('Volume Forecast'!$M$5:$M$212,'Volume Forecast'!$D$5:$D$212,$A14,'Volume Forecast'!$A$5:$A$212,F$12) -> 0 | G14: =SUMIFS('Volume Forecast'!$M$5:$M$212,'Volume Forecast'!$D$5:$D$212,$A14,'Volume Forecast'!$A$5:$A$212,G$12) -> 0 | H14: =SUMIFS('Volume Forecast'!$M$5:$M$212,'Volume Forecast'!$D$5:$D$212,$A14,'Volume Forecast'!$A$5:$A$212,H$12) -> 0 | I14: =SUMIFS('Volume Forecast'!$M$5:$M$212,'Volume Forecast'!$D$5:$D$212,$A14,'Volume Forecast'!$A$5:$A$212,I$12) -> 0 | J14: =SUMIFS('Volume Forecast'!$M$5:$M$212,'Volume Forecast'!$D$5:$D$212,$A14,'Volume Forecast'!$A$5:$A$212,J$12) -> 0 | ... AB14: =SUMIFS('Volume Forecast'!$M$5:$M$212,'Volume Forecast'!$D$5:$D$212,$A14,'Volume Forecast'!$A$5:$A$212,AB$12) -> 0
A15: CARR-C | B15: Carrier C | C15: =SUMIFS('Volume Forecast'!$M$5:$M$212,'Volume Forecast'!$D$5:$D$212,$A15,'Volume Forecast'!$A$5:$A$212,C$12) -> 0 | D15: =SUMIFS('Volume Forecast'!$M$5:$M$212,'Volume Forecast'!$D$5:$D$212,$A15,'Volume Forecast'!$A$5:$A$212,D$12) -> 0 | E15: =SUMIFS('Volume Forecast'!$M$5:$M$212,'Volume Forecast'!$D$5:$D$212,$A15,'Volume Forecast'!$A$5:$A$212,E$12) -> 0 | F15: =SUMIFS('Volume Forecast'!$M$5:$M$212,'Volume Forecast'!$D$5:$D$212,$A15,'Volume Forecast'!$A$5:$A$212,F$12) -> 0 | G15: =SUMIFS('Volume Forecast'!$M$5:$M$212,'Volume Forecast'!$D$5:$D$212,$A15,'Volume Forecast'!$A$5:$A$212,G$12) -> 0 | H15: =SUMIFS('Volume Forecast'!$M$5:$M$212,'Volume Forecast'!$D$5:$D$212,$A15,'Volume Forecast'!$A$5:$A$212,H$12) -> 0 | I15: =SUMIFS('Volume Forecast'!$M$5:$M$212,'Volume Forecast'!$D$5:$D$212,$A15,'Volume Forecast'!$A$5:$A$212,I$12) -> 0 | J15: =SUMIFS('Volume Forecast'!$M$5:$M$212,'Volume Forecast'!$D$5:$D$212,$A15,'Volume Forecast'!$A$5:$A$212,J$12) -> 0 | ... AB15: =SUMIFS('Volume Forecast'!$M$5:$M$212,'Volume Forecast'!$D$5:$D$212,$A15,'Volume Forecast'!$A$5:$A$212,AB$12) -> 0
A16: CARR-D | B16: Carrier D | C16: =SUMIFS('Volume Forecast'!$M$5:$M$212,'Volume Forecast'!$D$5:$D$212,$A16,'Volume Forecast'!$A$5:$A$212,C$12) -> 0 | D16: =SUMIFS('Volume Forecast'!$M$5:$M$212,'Volume Forecast'!$D$5:$D$212,$A16,'Volume Forecast'!$A$5:$A$212,D$12) -> 0 | E16: =SUMIFS('Volume Forecast'!$M$5:$M$212,'Volume Forecast'!$D$5:$D$212,$A16,'Volume Forecast'!$A$5:$A$212,E$12) -> 0 | F16: =SUMIFS('Volume Forecast'!$M$5:$M$212,'Volume Forecast'!$D$5:$D$212,$A16,'Volume Forecast'!$A$5:$A$212,F$12) -> 0 | G16: =SUMIFS('Volume Forecast'!$M$5:$M$212,'Volume Forecast'!$D$5:$D$212,$A16,'Volume Forecast'!$A$5:$A$212,G$12) -> 0 | H16: =SUMIFS('Volume Forecast'!$M$5:$M$212,'Volume Forecast'!$D$5:$D$212,$A16,'Volume Forecast'!$A$5:$A$212,H$12) -> 0 | I16: =SUMIFS('Volume Forecast'!$M$5:$M$212,'Volume Forecast'!$D$5:$D$212,$A16,'Volume Forecast'!$A$5:$A$212,I$12) -> 0 | J16: =SUMIFS('Volume Forecast'!$M$5:$M$212,'Volume Forecast'!$D$5:$D$212,$A16,'Volume Forecast'!$A$5:$A$212,J$12) -> 0 | ... AB16: =SUMIFS('Volume Forecast'!$M$5:$M$212,'Volume Forecast'!$D$5:$D$212,$A16,'Volume Forecast'!$A$5:$A$212,AB$12) -> 0
A18: Outlook notes to send carriers
A19: Forecast window: weeks ending Aug 01, 2026 to Jan 23, 2027.
A20: Trailer counts use each lane's trailing 52-week fill rate. The high case is the 80th percentile of backtest error.
A21: Carrier A (Albany, Hartford)
A22: Contracted capacity: 30 trailers per week across these lanes.
A23: Average forecast: 27 trailers per week, 514 pallets per week.
A24: Peak week: Dec 05, with 37 trailers forecast and up to 39 in the high case.
A25: Surge capacity needed in 6 weeks, from Nov 14 to Dec 19. Largest request: 9 extra trailers in one week.
A26: Carrier B (Worcester, Syracuse)
A27: Contracted capacity: 31 trailers per week across these lanes.
A28: Average forecast: 30 trailers per week, 578 pallets per week.
A29: Peak week: Dec 05, with 42 trailers forecast and up to 43 in the high case.
... A40: Surge capacity needed in 10 weeks, from Oct 24 to Dec 26. Largest request: 12 extra trailers in one week.

Sheet Store Visibility
A1: Store Visibility Report
A2: One row per store. Carrier, next-4-week volume, and status are formulas.
H3: Week ending: | I3: 46235 | J3: 46242 | K3: 46249 | L3: 46256
A4: Store | B4: Pool point | C4: Market | D4: Carrier | E4: Size | F4: Delivery days | G4: Pallet max | H4: Open date | I4: Wk Aug 01 | J4: Wk Aug 08 | K4: Wk Aug 15 | L4: Wk Aug 22 | M4: Peak wk forecast | N4: Peak wk planned | O4: Peak wk backlog | P4: Status
A5: S1001 | B5: PP01 | C5: Albany | D5: =INDEX('Pool Points'!$E:$E,MATCH(B5,'Pool Points'!$A:$A,0)) -> CARR-A | E5: Large | F5: Tue/Thu/Fri/Sat | G5: 7 | H5: 42005 | I5: =SUMIFS('Store Forecast'!$D$5:$D$3540,'Store Forecast'!$C$5:$C$3540,$A5,'Store Forecast'!$A$5:$A$3540,I$3) -> 25.8 | J5: =SUMIFS('Store Forecast'!$D$5:$D$3540,'Store Forecast'!$C$5:$C$3540,$A5,'Store Forecast'!$A$5:$A$3540,J$3) -> 27.2 | K5: =SUMIFS('Store Forecast'!$D$5:$D$3540,'Store Forecast'!$C$5:$C$3540,$A5,'Store Forecast'!$A$5:$A$3540,K$3) -> 25.4 | L5: =SUMIFS('Store Forecast'!$D$5:$D$3540,'Store Forecast'!$C$5:$C$3540,$A5,'Store Forecast'!$A$5:$A$3540,L$3) -> 25.3 | M5: 38.9 | N5: 28 | O5: 11 | P5: =IF(H5>AsOfDate,"Opens "&TEXT(H5,"mmm d"),IF(O5>0,"Backlog in peak week","On plan")) -> Backlog in peak week
A6: S1002 | B6: PP01 | C6: Albany | D6: =INDEX('Pool Points'!$E:$E,MATCH(B6,'Pool Points'!$A:$A,0)) -> CARR-A | E6: Large | F6: Tue/Thu/Fri/Sat | G6: 13 | H6: 42005 | I6: =SUMIFS('Store Forecast'!$D$5:$D$3540,'Store Forecast'!$C$5:$C$3540,$A6,'Store Forecast'!$A$5:$A$3540,I$3) -> 22.3 | J6: =SUMIFS('Store Forecast'!$D$5:$D$3540,'Store Forecast'!$C$5:$C$3540,$A6,'Store Forecast'!$A$5:$A$3540,J$3) -> 23.5 | K6: =SUMIFS('Store Forecast'!$D$5:$D$3540,'Store Forecast'!$C$5:$C$3540,$A6,'Store Forecast'!$A$5:$A$3540,K$3) -> 22 | L6: =SUMIFS('Store Forecast'!$D$5:$D$3540,'Store Forecast'!$C$5:$C$3540,$A6,'Store Forecast'!$A$5:$A$3540,L$3) -> 21.9 | M6: 33.6 | N6: 34 | O6: 0 | P6: =IF(H6>AsOfDate,"Opens "&TEXT(H6,"mmm d"),IF(O6>0,"Backlog in peak week","On plan")) -> On plan
A7: S1003 | B7: PP01 | C7: Albany | D7: =INDEX('Pool Points'!$E:$E,MATCH(B7,'Pool Points'!$A:$A,0)) -> CARR-A | E7: Medium | F7: Wed/Fri/Sat | G7: 14 | H7: 42005 | I7: =SUMIFS('Store Forecast'!$D$5:$D$3540,'Store Forecast'!$C$5:$C$3540,$A7,'Store Forecast'!$A$5:$A$3540,I$3) -> 17 | J7: =SUMIFS('Store Forecast'!$D$5:$D$3540,'Store Forecast'!$C$5:$C$3540,$A7,'Store Forecast'!$A$5:$A$3540,J$3) -> 17.9 | K7: =SUMIFS('Store Forecast'!$D$5:$D$3540,'Store Forecast'!$C$5:$C$3540,$A7,'Store Forecast'!$A$5:$A$3540,K$3) -> 16.7 | L7: =SUMIFS('Store Forecast'!$D$5:$D$3540,'Store Forecast'!$C$5:$C$3540,$A7,'Store Forecast'!$A$5:$A$3540,L$3) -> 16.7 | M7: 25.6 | N7: 26 | O7: 0 | P7: =IF(H7>AsOfDate,"Opens "&TEXT(H7,"mmm d"),IF(O7>0,"Backlog in peak week","On plan")) -> On plan
A8: S1004 | B8: PP01 | C8: Albany | D8: =INDEX('Pool Points'!$E:$E,MATCH(B8,'Pool Points'!$A:$A,0)) -> CARR-A | E8: Large | F8: Mon/Wed/Fri/Sat | G8: 13 | H8: 42005 | I8: =SUMIFS('Store Forecast'!$D$5:$D$3540,'Store Forecast'!$C$5:$C$3540,$A8,'Store Forecast'!$A$5:$A$3540,I$3) -> 24.4 | J8: =SUMIFS('Store Forecast'!$D$5:$D$3540,'Store Forecast'!$C$5:$C$3540,$A8,'Store Forecast'!$A$5:$A$3540,J$3) -> 25.7 | K8: =SUMIFS('Store Forecast'!$D$5:$D$3540,'Store Forecast'!$C$5:$C$3540,$A8,'Store Forecast'!$A$5:$A$3540,K$3) -> 24 | L8: =SUMIFS('Store Forecast'!$D$5:$D$3540,'Store Forecast'!$C$5:$C$3540,$A8,'Store Forecast'!$A$5:$A$3540,L$3) -> 23.9 | M8: 36.8 | N8: 37 | O8: 0 | P8: =IF(H8>AsOfDate,"Opens "&TEXT(H8,"mmm d"),IF(O8>0,"Backlog in peak week","On plan")) -> On plan
A9: S1005 | B9: PP01 | C9: Albany | D9: =INDEX('Pool Points'!$E:$E,MATCH(B9,'Pool Points'!$A:$A,0)) -> CARR-A | E9: Small | F9: Mon/Thu/Sat | G9: 9 | H9: 42005 | I9: =SUMIFS('Store Forecast'!$D$5:$D$3540,'Store Forecast'!$C$5:$C$3540,$A9,'Store Forecast'!$A$5:$A$3540,I$3) -> 10.7 | J9: =SUMIFS('Store Forecast'!$D$5:$D$3540,'Store Forecast'!$C$5:$C$3540,$A9,'Store Forecast'!$A$5:$A$3540,J$3) -> 11.2 | K9: =SUMIFS('Store Forecast'!$D$5:$D$3540,'Store Forecast'!$C$5:$C$3540,$A9,'Store Forecast'!$A$5:$A$3540,K$3) -> 10.5 | L9: =SUMIFS('Store Forecast'!$D$5:$D$3540,'Store Forecast'!$C$5:$C$3540,$A9,'Store Forecast'!$A$5:$A$3540,L$3) -> 10.5 | M9: 16.1 | N9: 16 | O9: 0 | P9: =IF(H9>AsOfDate,"Opens "&TEXT(H9,"mmm d"),IF(O9>0,"Backlog in peak week","On plan")) -> On plan
A10: S1006 | B10: PP01 | C10: Albany | D10: =INDEX('Pool Points'!$E:$E,MATCH(B10,'Pool Points'!$A:$A,0)) -> CARR-A | E10: Medium | F10: Tue/Fri/Sat | G10: 12 | H10: 42005 | I10: =SUMIFS('Store Forecast'!$D$5:$D$3540,'Store Forecast'!$C$5:$C$3540,$A10,'Store Forecast'!$A$5:$A$3540,I$3) -> 13.7 | J10: =SUMIFS('Store Forecast'!$D$5:$D$3540,'Store Forecast'!$C$5:$C$3540,$A10,'Store Forecast'!$A$5:$A$3540,J$3) -> 14.4 | K10: =SUMIFS('Store Forecast'!$D$5:$D$3540,'Store Forecast'!$C$5:$C$3540,$A10,'Store Forecast'!$A$5:$A$3540,K$3) -> 13.4 | L10: =SUMIFS('Store Forecast'!$D$5:$D$3540,'Store Forecast'!$C$5:$C$3540,$A10,'Store Forecast'!$A$5:$A$3540,L$3) -> 13.4 | M10: 20.6 | N10: 21 | O10: 0 | P10: =IF(H10>AsOfDate,"Opens "&TEXT(H10,"mmm d"),IF(O10>0,"Backlog in peak week","On plan")) -> On plan
A11: S1007 | B11: PP01 | C11: Albany | D11: =INDEX('Pool Points'!$E:$E,MATCH(B11,'Pool Points'!$A:$A,0)) -> CARR-A | E11: Small | F11: Wed/Fri/Sat | G11: 9 | H11: 42005 | I11: =SUMIFS('Store Forecast'!$D$5:$D$3540,'Store Forecast'!$C$5:$C$3540,$A11,'Store Forecast'!$A$5:$A$3540,I$3) -> 10.3 | J11: =SUMIFS('Store Forecast'!$D$5:$D$3540,'Store Forecast'!$C$5:$C$3540,$A11,'Store Forecast'!$A$5:$A$3540,J$3) -> 10.8 | K11: =SUMIFS('Store Forecast'!$D$5:$D$3540,'Store Forecast'!$C$5:$C$3540,$A11,'Store Forecast'!$A$5:$A$3540,K$3) -> 10.1 | L11: =SUMIFS('Store Forecast'!$D$5:$D$3540,'Store Forecast'!$C$5:$C$3540,$A11,'Store Forecast'!$A$5:$A$3540,L$3) -> 10.1 | M11: 15.5 | N11: 16 | O11: 0 | P11: =IF(H11>AsOfDate,"Opens "&TEXT(H11,"mmm d"),IF(O11>0,"Backlog in peak week","On plan")) -> On plan
A12: S1008 | B12: PP01 | C12: Albany | D12: =INDEX('Pool Points'!$E:$E,MATCH(B12,'Pool Points'!$A:$A,0)) -> CARR-A | E12: Medium | F12: Mon/Thu/Sat | G12: 17 | H12: 45556 | I12: =SUMIFS('Store Forecast'!$D$5:$D$3540,'Store Forecast'!$C$5:$C$3540,$A12,'Store Forecast'!$A$5:$A$3540,I$3) -> 20.2 | J12: =SUMIFS('Store Forecast'!$D$5:$D$3540,'Store Forecast'!$C$5:$C$3540,$A12,'Store Forecast'!$A$5:$A$3540,J$3) -> 21.2 | K12: =SUMIFS('Store Forecast'!$D$5:$D$3540,'Store Forecast'!$C$5:$C$3540,$A12,'Store Forecast'!$A$5:$A$3540,K$3) -> 19.8 | L12: =SUMIFS('Store Forecast'!$D$5:$D$3540,'Store Forecast'!$C$5:$C$3540,$A12,'Store Forecast'!$A$5:$A$3540,L$3) -> 19.8 | M12: 30.4 | N12: 30 | O12: 0 | P12: =IF(H12>AsOfDate,"Opens "&TEXT(H12,"mmm d"),IF(O12>0,"Backlog in peak week","On plan")) -> On plan
A13: S1009 | B13: PP01 | C13: Albany | D13: =INDEX('Pool Points'!$E:$E,MATCH(B13,'Pool Points'!$A:$A,0)) -> CARR-A | E13: Medium | F13: Mon/Wed/Fri/Sat | G13: 9 | H13: 42005 | I13: =SUMIFS('Store Forecast'!$D$5:$D$3540,'Store Forecast'!$C$5:$C$3540,$A13,'Store Forecast'!$A$5:$A$3540,I$3) -> 16 | J13: =SUMIFS('Store Forecast'!$D$5:$D$3540,'Store Forecast'!$C$5:$C$3540,$A13,'Store Forecast'!$A$5:$A$3540,J$3) -> 16.8 | K13: =SUMIFS('Store Forecast'!$D$5:$D$3540,'Store Forecast'!$C$5:$C$3540,$A13,'Store Forecast'!$A$5:$A$3540,K$3) -> 15.7 | L13: =SUMIFS('Store Forecast'!$D$5:$D$3540,'Store Forecast'!$C$5:$C$3540,$A13,'Store Forecast'!$A$5:$A$3540,L$3) -> 15.7 | M13: 24.1 | N13: 24 | O13: 0 | P13: =IF(H13>AsOfDate,"Opens "&TEXT(H13,"mmm d"),IF(O13>0,"Backlog in peak week","On plan")) -> On plan
A14: S1010 | B14: PP01 | C14: Albany | D14: =INDEX('Pool Points'!$E:$E,MATCH(B14,'Pool Points'!$A:$A,0)) -> CARR-A | E14: Small | F14: Mon/Thu/Sat | G14: 9 | H14: 42005 | I14: =SUMIFS('Store Forecast'!$D$5:$D$3540,'Store Forecast'!$C$5:$C$3540,$A14,'Store Forecast'!$A$5:$A$3540,I$3) -> 10.3 | J14: =SUMIFS('Store Forecast'!$D$5:$D$3540,'Store Forecast'!$C$5:$C$3540,$A14,'Store Forecast'!$A$5:$A$3540,J$3) -> 10.9 | K14: =SUMIFS('Store Forecast'!$D$5:$D$3540,'Store Forecast'!$C$5:$C$3540,$A14,'Store Forecast'!$A$5:$A$3540,K$3) -> 10.2 | L14: =SUMIFS('Store Forecast'!$D$5:$D$3540,'Store Forecast'!$C$5:$C$3540,$A14,'Store Forecast'!$A$5:$A$3540,L$3) -> 10.2 | M14: 15.6 | N14: 16 | O14: 0 | P14: =IF(H14>AsOfDate,"Opens "&TEXT(H14,"mmm d"),IF(O14>0,"Backlog in peak week","On plan")) -> On plan
A15: S1011 | B15: PP01 | C15: Albany | D15: =INDEX('Pool Points'!$E:$E,MATCH(B15,'Pool Points'!$A:$A,0)) -> CARR-A | E15: Large | F15: Mon/Wed/Fri/Sat | G15: 10 | H15: 42005 | I15: =SUMIFS('Store Forecast'!$D$5:$D$3540,'Store Forecast'!$C$5:$C$3540,$A15,'Store Forecast'!$A$5:$A$3540,I$3) -> 18.8 | J15: =SUMIFS('Store Forecast'!$D$5:$D$3540,'Store Forecast'!$C$5:$C$3540,$A15,'Store Forecast'!$A$5:$A$3540,J$3) -> 19.8 | K15: =SUMIFS('Store Forecast'!$D$5:$D$3540,'Store Forecast'!$C$5:$C$3540,$A15,'Store Forecast'!$A$5:$A$3540,K$3) -> 18.5 | L15: =SUMIFS('Store Forecast'!$D$5:$D$3540,'Store Forecast'!$C$5:$C$3540,$A15,'Store Forecast'!$A$5:$A$3540,L$3) -> 18.5 | M15: 28.4 | N15: 28 | O15: 0 | P15: =IF(H15>AsOfDate,"Opens "&TEXT(H15,"mmm d"),IF(O15>0,"Backlog in peak week","On plan")) -> On plan
A16: S1012 | B16: PP01 | C16: Albany | D16: =INDEX('Pool Points'!$E:$E,MATCH(B16,'Pool Points'!$A:$A,0)) -> CARR-A | E16: Large | F16: Mon/Wed/Fri/Sat | G16: 13 | H16: 42005 | I16: =SUMIFS('Store Forecast'!$D$5:$D$3540,'Store Forecast'!$C$5:$C$3540,$A16,'Store Forecast'!$A$5:$A$3540,I$3) -> 22.9 | J16: =SUMIFS('Store Forecast'!$D$5:$D$3540,'Store Forecast'!$C$5:$C$3540,$A16,'Store Forecast'!$A$5:$A$3540,J$3) -> 24.2 | K16: =SUMIFS('Store Forecast'!$D$5:$D$3540,'Store Forecast'!$C$5:$C$3540,$A16,'Store Forecast'!$A$5:$A$3540,K$3) -> 22.6 | L16: =SUMIFS('Store Forecast'!$D$5:$D$3540,'Store Forecast'!$C$5:$C$3540,$A16,'Store Forecast'!$A$5:$A$3540,L$3) -> 22.5 | M16: 34.6 | N16: 35 | O16: 0 | P16: =IF(H16>AsOfDate,"Opens "&TEXT(H16,"mmm d"),IF(O16>0,"Backlog in peak week","On plan")) -> On plan
... A141: S1137 | B141: PP04 | C141: Harrisburg | D141: =INDEX('Pool Points'!$E:$E,MATCH(B141,'Pool Points'!$A:$A,0)) -> CARR-C | E141: Medium | F141: Tue/Fri/Sat | G141: 13 | H141: 46361 | I141: =SUMIFS('Store Forecast'!$D$5:$D$3540,'Store Forecast'!$C$5:$C$3540,$A141,'Store Forecast'!$A$5:$A$3540,I$3) -> 0 | J141: =SUMIFS('Store Forecast'!$D$5:$D$3540,'Store Forecast'!$C$5:$C$3540,$A141,'Store Forecast'!$A$5:$A$3540,J$3) -> 0 | K141: =SUMIFS('Store Forecast'!$D$5:$D$3540,'Store Forecast'!$C$5:$C$3540,$A141,'Store Forecast'!$A$5:$A$3540,K$3) -> 0 | L141: =SUMIFS('Store Forecast'!$D$5:$D$3540,'Store Forecast'!$C$5:$C$3540,$A141,'Store Forecast'!$A$5:$A$3540,L$3) -> 0 | M141: 26 | N141: 26 | O141: 0 | P141: =IF(H141>AsOfDate,"Opens "&TEXT(H141,"mmm d"),IF(O141>0,"Backlog in peak week","On plan")) -> Opens Dec 5

Sheet Peak Week Schedule
A1: Peak Week Delivery Schedule, week ending Dec 05, 2026
A2: Pallets per delivery after change requests and mitigation. Orange cells are at the store's pallet max.
A4: Store | B4: Pool point | C4: Delivery days | D4: Pallet max | E4: Mon | F4: Tue | G4: Wed | H4: Thu | I4: Fri | J4: Sat | K4: Planned total | L4: Forecast | M4: Backlog
A5: S1001 | B5: PP01 | C5: Tue/Thu/Fri/Sat | D5: 7 | F5: 7 | H5: 7 | I5: 7 | J5: 7 | K5: =SUM(E5:J5) -> 28 | L5: 38.9 | M5: =MAX(0,ROUND(L5,0)-K5) -> 11
A6: S1002 | B6: PP01 | C6: Tue/Thu/Fri/Sat | D6: 13 | F6: 9 | H6: 9 | I6: 8 | J6: 8 | K6: =SUM(E6:J6) -> 34 | L6: 33.6 | M6: =MAX(0,ROUND(L6,0)-K6) -> 0
A7: S1003 | B7: PP01 | C7: Wed/Fri/Sat | D7: 14 | G7: 9 | I7: 9 | J7: 8 | K7: =SUM(E7:J7) -> 26 | L7: 25.6 | M7: =MAX(0,ROUND(L7,0)-K7) -> 0
A8: S1004 | B8: PP01 | C8: Mon/Wed/Fri/Sat | D8: 13 | E8: 10 | G8: 9 | I8: 9 | J8: 9 | K8: =SUM(E8:J8) -> 37 | L8: 36.8 | M8: =MAX(0,ROUND(L8,0)-K8) -> 0
A9: S1005 | B9: PP01 | C9: Mon/Thu/Sat | D9: 9 | E9: 6 | H9: 5 | J9: 5 | K9: =SUM(E9:J9) -> 16 | L9: 16.1 | M9: =MAX(0,ROUND(L9,0)-K9) -> 0
A10: S1006 | B10: PP01 | C10: Tue/Fri/Sat | D10: 12 | F10: 7 | I10: 7 | J10: 7 | K10: =SUM(E10:J10) -> 21 | L10: 20.6 | M10: =MAX(0,ROUND(L10,0)-K10) -> 0
A11: S1007 | B11: PP01 | C11: Wed/Fri/Sat | D11: 9 | G11: 6 | I11: 5 | J11: 5 | K11: =SUM(E11:J11) -> 16 | L11: 15.5 | M11: =MAX(0,ROUND(L11,0)-K11) -> 0
A12: S1008 | B12: PP01 | C12: Mon/Thu/Sat | D12: 17 | E12: 10 | H12: 10 | J12: 10 | K12: =SUM(E12:J12) -> 30 | L12: 30.4 | M12: =MAX(0,ROUND(L12,0)-K12) -> 0
A13: S1009 | B13: PP01 | C13: Mon/Wed/Fri/Sat | D13: 9 | E13: 6 | G13: 6 | I13: 6 | J13: 6 | K13: =SUM(E13:J13) -> 24 | L13: 24.1 | M13: =MAX(0,ROUND(L13,0)-K13) -> 0
A14: S1010 | B14: PP01 | C14: Mon/Thu/Sat | D14: 9 | E14: 6 | H14: 5 | J14: 5 | K14: =SUM(E14:J14) -> 16 | L14: 15.6 | M14: =MAX(0,ROUND(L14,0)-K14) -> 0
A15: S1011 | B15: PP01 | C15: Mon/Wed/Fri/Sat | D15: 10 | E15: 7 | G15: 7 | I15: 7 | J15: 7 | K15: =SUM(E15:J15) -> 28 | L15: 28.4 | M15: =MAX(0,ROUND(L15,0)-K15) -> 0
A16: S1012 | B16: PP01 | C16: Mon/Wed/Fri/Sat | D16: 13 | E16: 9 | G16: 9 | I16: 9 | J16: 8 | K16: =SUM(E16:J16) -> 35 | L16: 34.6 | M16: =MAX(0,ROUND(L16,0)-K16) -> 0
